<?xml version="1.0" encoding="utf-8"?>
<robot name="rr_bot">
    <link name="world">
        <inertial>
            <origin rpy="0 0 0" xyz="0 0 0"/>
            <mass value="1000"/>
            <inertia ixx="1000.0" ixy="0.0" ixz="0.0" iyy="1000.0" iyz="0.0" izz="1000.0"/>
        </inertial>
    </link>
    <joint name="rr_bot_fixed" type="fixed">
        <origin rpy="0 0 0" xyz="0 0 0"/>
        <parent link="world"/>
        <child link="rr_bot_link1"/>
    </joint>
    <link name="rr_bot_link1">
        <collision>
            <origin rpy="0 0 0" xyz="0 0 1.0"/>
            <geometry>
                <box size="0.1 0.1 2"/>
            </geometry>
        </collision>
        <visual name="rr_bot_link1_visual">
            <origin rpy="0 0 0" xyz="0 0 1.0"/>
            <geometry>
                <box size="0.1 0.1 2"/>
            </geometry>
        </visual>
        <inertial>
            <origin rpy="0 0 0" xyz="0 0 1.0"/>
            <mass value="1"/>
            <inertia ixx="1.0" ixy="0.0" ixz="0.0" iyy="1.0" iyz="0.0" izz="1.0"/>
        </inertial>
    </link>
    <joint name="rr_bot_joint1" type="revolute">
        <parent link="rr_bot_link1"/>
        <child link="rr_bot_link2"/>
        <origin rpy="0 0 0" xyz="0 0.1 1.95"/>
        <axis xyz="0 1 0"/>
        <dynamics damping="0.7"/>
    </joint>
    <link name="rr_bot_link2">
        <collision name="rr_bot_link2_collision">
            <origin rpy="0 0 0" xyz="0 0 0.45"/>
              <geometry>
                <box size="0.1 0.1 1"/>
            </geometry>
        </collision>
        <visual name="rr_bot_link2_visual">
            <origin rpy="0 0 0" xyz="0 0 0.45"/>
            <geometry>
                <box size="0.1 0.1 1"/>
            </geometry>
        </visual>
        <inertial>
            <origin rpy="0 0 0" xyz="0 0 0.45"/>
            <mass value="1"/>
            <inertia ixx="1.0" ixy="0.0" ixz="0.0" iyy="1.0" iyz="0.0" izz="1.0"/>
        </inertial>
    </link>
    <joint name="rr_bot_joint2" type="revolute">
        <parent link="rr_bot_link2"/>
        <child link="rr_bot_link3"/>
        <origin rpy="0 0 0" xyz="0 0.1 0.9"/>
        <axis xyz="0 1 0"/>
        <dynamics damping="0.7"/>
    </joint>
    <link name="rr_bot_link3">
        <collision name="rr_bot_link3_collision">
            <origin rpy="0 0 0" xyz="0 0 0.45"/>
            <geometry>
                <box size="0.1 0.1 1"/>
            </geometry>
        </collision>
        <visual name="rr_bot_link3_visual">
            <origin rpy="0 0 0" xyz="0 0 0.45"/>
            <geometry>
                <box size="0.1 0.1 1"/>
            </geometry>
        </visual>
        <inertial>
            <origin rpy="0 0 0" xyz="0 0 0.45"/>
            <mass value="1"/>
            <inertia ixx="1.0" ixy="0.0" ixz="0.0" iyy="1.0" iyz="0.0" izz="1.0"/>
        </inertial>
    </link>
    <joint name="rr_bot_hokuyo_joint" type="fixed">
        <axis xyz="0 1 0"/>
        <origin rpy="0 0 0" xyz="0 0 0.975"/>
        <parent link="rr_bot_link3"/>
        <child link="rr_bot_hokuyo_link"/>
    </joint>
    <link name="rr_bot_hokuyo_link">
        <collision name="rr_bot_hokuyo_link_collision">
            <origin rpy="0 0 0" xyz="0 0 0"/>
            <geometry>
                <box size="0.1 0.1 0.1"/>
            </geometry>
        </collision>
        <visual name="rr_bot_hokuyo_link_visual">
            <origin rpy="0 0 0" xyz="0 0 0"/>
            <geometry>
                <box size="0.1 0.1 0.1"/>
            </geometry>
        </visual>
        <inertial>
            <mass value="1e-5"/>
            <origin rpy="0 0 0" xyz="0 0 0"/>
            <inertia ixx="1e-6" ixy="0" ixz="0" iyy="1e-6" iyz="0" izz="1e-6"/>
        </inertial>
    </link>
    <joint name="rr_bot_camera_joint" type="fixed">
        <axis xyz="0 1 0"/>
        <origin rpy="0 0 0" xyz="0.05 0 0.9"/>
        <parent link="rr_bot_link3"/>
        <child link="rr_bot_camera_link"/>
    </joint>
    <link name="rr_bot_camera_link">
        <collision name="rr_bot_camera_link_collision">
            <origin rpy="0 0 0" xyz="0 0 0"/>
            <geometry>
                <box size="0.05 0.05 0.05"/>
            </geometry>
        </collision>
        <visual name="rr_bot_camera_link_visual">
            <origin rpy="0 0 0" xyz="0 0 0"/>
            <geometry>
                <box size="0.05 0.05 0.05"/>
            </geometry>
        </visual>
        <inertial>
            <mass value="1e-5"/>
            <origin rpy="0 0 0" xyz="0 0 0"/>
            <inertia ixx="1e-6" ixy="0" ixz="0" iyy="1e-6" iyz="0" izz="1e-6"/>
        </inertial>
    </link>
</robot>
